Workbook

Sheet Startsida
A1: VM-tips 2026 – Topplista & statistik
A3: Snabbstatus | H3: Topp 10
A4: Matcher totalt | B4: 104 | H4: Placering | I4: Namn | J4: Poäng | K4: Exakta | L4: Rätt tecken
A5: Matcher med facit | B5: =COUNT(Matchschema!K2:K105) -> 1 | H5: =IFERROR(INDEX($A$12:$A$41,MATCH(1,$A$12:$A$41,0)),"") -> 1 | I5: =IFERROR(INDEX($B$12:$B$41,MATCH(1,$A$12:$A$41,0)),"") -> Ricardo | J5: =IFERROR(INDEX($C$12:$C$41,MATCH(1,$A$12:$A$41,0)),"") -> 3 | K5: =IFERROR(INDEX($D$12:$D$41,MATCH(1,$A$12:$A$41,0)),"") -> 1 | L5: =IFERROR(INDEX($E$12:$E$41,MATCH(1,$A$12:$A$41,0)),"") -> 1
A6: Antal spelare | B6: 30 | H6: =IFERROR(INDEX($A$12:$A$41,MATCH(2,$A$12:$A$41,0)),"") -> 2 | I6: =IFERROR(INDEX($B$12:$B$41,MATCH(2,$A$12:$A$41,0)),"") -> Stina | J6: =IFERROR(INDEX($C$12:$C$41,MATCH(2,$A$12:$A$41,0)),"") -> 3 | K6: =IFERROR(INDEX($D$12:$D$41,MATCH(2,$A$12:$A$41,0)),"") -> 1 | L6: =IFERROR(INDEX($E$12:$E$41,MATCH(2,$A$12:$A$41,0)),"") -> 1
A7: Genomsnittspoäng | B7: =IFERROR(AVERAGE(C12:C41),0) -> 1.0333333 | H7: =IFERROR(INDEX($A$12:$A$41,MATCH(3,$A$12:$A$41,0)),"") -> 3 | I7: =IFERROR(INDEX($B$12:$B$41,MATCH(3,$A$12:$A$41,0)),"") -> Robban | J7: =IFERROR(INDEX($C$12:$C$41,MATCH(3,$A$12:$A$41,0)),"") -> 3 | K7: =IFERROR(INDEX($D$12:$D$41,MATCH(3,$A$12:$A$41,0)),"") -> 1 | L7: =IFERROR(INDEX($E$12:$E$41,MATCH(3,$A$12:$A$41,0)),"") -> 1
A8: Högsta poäng | B8: =IFERROR(MAX(C12:C41),0) -> 3 | H8: =IFERROR(INDEX($A$12:$A$41,MATCH(4,$A$12:$A$41,0)),"") -> 4 | I8: =IFERROR(INDEX($B$12:$B$41,MATCH(4,$A$12:$A$41,0)),"") -> Clabbe | J8: =IFERROR(INDEX($C$12:$C$41,MATCH(4,$A$12:$A$41,0)),"") -> 3 | K8: =IFERROR(INDEX($D$12:$D$41,MATCH(4,$A$12:$A$41,0)),"") -> 1 | L8: =IFERROR(INDEX($E$12:$E$41,MATCH(4,$A$12:$A$41,0)),"") -> 1
H9: =IFERROR(INDEX($A$12:$A$41,MATCH(5,$A$12:$A$41,0)),"") -> 5 | I9: =IFERROR(INDEX($B$12:$B$41,MATCH(5,$A$12:$A$41,0)),"") -> Dennis | J9: =IFERROR(INDEX($C$12:$C$41,MATCH(5,$A$12:$A$41,0)),"") -> 3 | K9: =IFERROR(INDEX($D$12:$D$41,MATCH(5,$A$12:$A$41,0)),"") -> 1 | L9: =IFERROR(INDEX($E$12:$E$41,MATCH(5,$A$12:$A$41,0)),"") -> 1
H10: =IFERROR(INDEX($A$12:$A$41,MATCH(6,$A$12:$A$41,0)),"") -> 6 | I10: =IFERROR(INDEX($B$12:$B$41,MATCH(6,$A$12:$A$41,0)),"") -> Nizze | J10: =IFERROR(INDEX($C$12:$C$41,MATCH(6,$A$12:$A$41,0)),"") -> 3 | K10: =IFERROR(INDEX($D$12:$D$41,MATCH(6,$A$12:$A$41,0)),"") -> 1 | L10: =IFERROR(INDEX($E$12:$E$41,MATCH(6,$A$12:$A$41,0)),"") -> 1
A11: Rank | B11: Namn | C11: Poäng | D11: Exakta | E11: Rätt tecken | F11: Flik | H11: =IFERROR(INDEX($A$12:$A$41,MATCH(7,$A$12:$A$41,0)),"") -> 7 | I11: =IFERROR(INDEX($B$12:$B$41,MATCH(7,$A$12:$A$41,0)),"") -> Janne | J11: =IFERROR(INDEX($C$12:$C$41,MATCH(7,$A$12:$A$41,0)),"") -> 1 | K11: =IFERROR(INDEX($D$12:$D$41,MATCH(7,$A$12:$A$41,0)),"") -> 0 | L11: =IFERROR(INDEX($E$12:$E$41,MATCH(7,$A$12:$A$41,0)),"") -> 1
A12: =IF(C12="","",1+COUNTIF($C$12:$C$41,">"&C12)+COUNTIFS($C$12:C12,C12)-1) -> 1 | B12: =Ricardo!$B$2 -> Ricardo | C12: =Ricardo!$G$2 -> 3 | D12: =Ricardo!$J$2 -> 1 | E12: =Ricardo!$L$2 -> 1 | F12: Spelare 01 | H12: =IFERROR(INDEX($A$12:$A$41,MATCH(8,$A$12:$A$41,0)),"") -> 8 | I12: =IFERROR(INDEX($B$12:$B$41,MATCH(8,$A$12:$A$41,0)),"") -> Bosse | J12: =IFERROR(INDEX($C$12:$C$41,MATCH(8,$A$12:$A$41,0)),"") -> 1 | K12: =IFERROR(INDEX($D$12:$D$41,MATCH(8,$A$12:$A$41,0)),"") -> 0 | L12: =IFERROR(INDEX($E$12:$E$41,MATCH(8,$A$12:$A$41,0)),"") -> 1
A13: =IF(C13="","",1+COUNTIF($C$12:$C$41,">"&C13)+COUNTIFS($C$12:C13,C13)-1) -> 7 | B13: =Janne!$B$2 -> Janne | C13: =Janne!$G$2 -> 1 | D13: =Janne!$J$2 -> 0 | E13: =Janne!$L$2 -> 1 | F13: Spelare 02 | H13: =IFERROR(INDEX($A$12:$A$41,MATCH(9,$A$12:$A$41,0)),"") -> 9 | I13: =IFERROR(INDEX($B$12:$B$41,MATCH(9,$A$12:$A$41,0)),"") -> Chrille | J13: =IFERROR(INDEX($C$12:$C$41,MATCH(9,$A$12:$A$41,0)),"") -> 1 | K13: =IFERROR(INDEX($D$12:$D$41,MATCH(9,$A$12:$A$41,0)),"") -> 0 | L13: =IFERROR(INDEX($E$12:$E$41,MATCH(9,$A$12:$A$41,0)),"") -> 1
A14: =IF(C14="","",1+COUNTIF($C$12:$C$41,">"&C14)+COUNTIFS($C$12:C14,C14)-1) -> 8 | B14: =Bosse!$B$2 -> Bosse | C14: =Bosse!$G$2 -> 1 | D14: =Bosse!$J$2 -> 0 | E14: =Bosse!$L$2 -> 1 | F14: Spelare 03 | H14: =IFERROR(INDEX($A$12:$A$41,MATCH(10,$A$12:$A$41,0)),"") -> 10 | I14: =IFERROR(INDEX($B$12:$B$41,MATCH(10,$A$12:$A$41,0)),"") -> John T. | J14: =IFERROR(INDEX($C$12:$C$41,MATCH(10,$A$12:$A$41,0)),"") -> 1 | K14: =IFERROR(INDEX($D$12:$D$41,MATCH(10,$A$12:$A$41,0)),"") -> 0 | L14: =IFERROR(INDEX($E$12:$E$41,MATCH(10,$A$12:$A$41,0)),"") -> 1
A15: =IF(C15="","",1+COUNTIF($C$12:$C$41,">"&C15)+COUNTIFS($C$12:C15,C15)-1) -> 2 | B15: =Stina!$B$2 -> Stina | C15: =Stina!$G$2 -> 3 | D15: =Stina!$J$2 -> 1 | E15: =Stina!$L$2 -> 1 | F15: Spelare 04
A16: =IF(C16="","",1+COUNTIF($C$12:$C$41,">"&C16)+COUNTIFS($C$12:C16,C16)-1) -> 3 | B16: =Robban!$B$2 -> Robban | C16: =Robban!$G$2 -> 3 | D16: =Robban!$J$2 -> 1 | E16: =Robban!$L$2 -> 1 | F16: Spelare 05
A17: =IF(C17="","",1+COUNTIF($C$12:$C$41,">"&C17)+COUNTIFS($C$12:C17,C17)-1) -> 9 | B17: =Chrille!$B$2 -> Chrille | C17: =Chrille!$G$2 -> 1 | D17: =Chrille!$J$2 -> 0 | E17: =Chrille!$L$2 -> 1 | F17: Spelare 06 | H17: Rolig statistik från tipsen
A18: =IF(C18="","",1+COUNTIF($C$12:$C$41,">"&C18)+COUNTIFS($C$12:C18,C18)-1) -> 10 | B18: ='John T.'!$B$2 -> John T. | C18: ='John T.'!$G$2 -> 1 | D18: ='John T.'!$J$2 -> 0 | E18: ='John T.'!$L$2 -> 1 | F18: Spelare 07 | H18: Nyckeltal | I18: Värde | K18: Populäraste tecknet | L18: Antal | M18: Mest tippade mål totalt | N18: Antal
A19: =IF(C19="","",1+COUNTIF($C$12:$C$41,">"&C19)+COUNTIFS($C$12:C19,C19)-1) -> 4 | B19: =Clabbe!$B$2 -> Clabbe | C19: =Clabbe!$G$2 -> 3 | D19: =Clabbe!$J$2 -> 1 | E19: =Clabbe!$L$2 -> 1 | F19: Spelare 08 | H19: Antal inlämnade matchtips | I19: =(COUNT(Ricardo!I7:J110)+COUNT(Janne!I7:J110)+COUNT(Bosse!I7:J110)+COUNT(Stina!I7:J110)+COUNT(Robban!I7:J110)+COUNT(Chrille!I7:J110)+COUNT('John T.'!I7:J110)+COUNT(Clabbe!I7:J110)+COUNT(Dennis!I7:J110)+COUNT(Monfors!I7:J110)+COUNT('Anders D.'!I7:J110)+COUNT(Evelina!I7:J110)+COUNT(Nizze!I7:J110)+COUNT(Sorken!I7:J110)+COUNT(Peter!I7:J110)+COUNT(Antonia!I7:J110)+COUNT('Niklas A.'!I7:J110)+COUNT('Thomas B.'!I7:J110)+COUNT(Micke!I7:J110)+COUNT(Robin!I7:J110)+COUNT('Spelare 21'!I7:J110)+COUNT('Spelare 22'!I7:J110)+COUNT('Spelare 23'!I7:J110)+COUNT('Spelare 24'!I7:J110)+COUNT('Spelare 25'!I7:J110)+COUNT('Spelare 26'!I7:J110)+COUNT('Spelare 27'!I7:J110)+COUNT('Spelare 28'!I7:J110)+COUNT('Spelare 29'!I7:J110)+COUNT('Spelare 30'!I7:J110))/2 -> 2080 | K19: 1 | L19: =COUNTIF(Ricardo!K7:K110,"1")+COUNTIF(Janne!K7:K110,"1")+COUNTIF(Bosse!K7:K110,"1")+COUNTIF(Stina!K7:K110,"1")+COUNTIF(Robban!K7:K110,"1")+COUNTIF(Chrille!K7:K110,"1")+COUNTIF('John T.'!K7:K110,"1")+COUNTIF(Clabbe!K7:K110,"1")+COUNTIF(Dennis!K7:K110,"1")+COUNTIF(Monfors!K7:K110,"1")+COUNTIF('Anders D.'!K7:K110,"1")+COUNTIF(Evelina!K7:K110,"1")+COUNTIF(Nizze!K7:K110,"1")+COUNTIF(Sorken!K7:K110,"1")+COUNTIF(Peter!K7:K110,"1")+COUNTIF(Antonia!K7:K110,"1")+COUNTIF('Niklas A.'!K7:K110,"1")+COUNTIF('Thomas B.'!K7:K110,"1")+COUNTIF(Micke!K7:K110,"1")+COUNTIF(Robin!K7:K110,"1")+COUNTIF('Spelare 21'!K7:K110,"1")+COUNTIF('Spelare 22'!K7:K110,"1")+COUNTIF('Spelare 23'!K7:K110,"1")+COUNTIF('Spelare 24'!K7:K110,"1")+COUNTIF('Spelare 25'!K7:K110,"1")+COUNTIF('Spelare 26'!K7:K110,"1")+COUNTIF('Spelare 27'!K7:K110,"1")+COUNTIF('Spelare 28'!K7:K110,"1")+COUNTIF('Spelare 29'!K7:K110,"1")+COUNTIF('Spelare 30'!K7:K110,"1") -> 961 | M19: 0 | N19: =COUNTIF(Ricardo!I7:J110,0)+COUNTIF(Janne!I7:J110,0)+COUNTIF(Bosse!I7:J110,0)+COUNTIF(Stina!I7:J110,0)+COUNTIF(Robban!I7:J110,0)+COUNTIF(Chrille!I7:J110,0)+COUNTIF('John T.'!I7:J110,0)+COUNTIF(Clabbe!I7:J110,0)+COUNTIF(Dennis!I7:J110,0)+COUNTIF(Monfors!I7:J110,0)+COUNTIF('Anders D.'!I7:J110,0)+COUNTIF(Evelina!I7:J110,0)+COUNTIF(Nizze!I7:J110,0)+COUNTIF(Sorken!I7:J110,0)+COUNTIF(Peter!I7:J110,0)+COUNTIF(Antonia!I7:J110,0)+COUNTIF('Niklas A.'!I7:J110,0)+COUNTIF('Thomas B.'!I7:J110,0)+COUNTIF(Micke!I7:J110,0)+COUNTIF(Robin!I7:J110,0)+COUNTIF('Spelare 21'!I7:J110,0)+COUNTIF('Spelare 22'!I7:J110,0)+COUNTIF('Spelare 23'!I7:J110,0)+COUNTIF('Spelare 24'!I7:J110,0)+COUNTIF('Spelare 25'!I7:J110,0)+COUNTIF('Spelare 26'!I7:J110,0)+COUNTIF('Spelare 27'!I7:J110,0)+COUNTIF('Spelare 28'!I7:J110,0)+COUNTIF('Spelare 29'!I7:J110,0)+COUNTIF('Spelare 30'!I7:J110,0) -> 1195
A20: =IF(C20="","",1+COUNTIF($C$12:$C$41,">"&C20)+COUNTIFS($C$12:C20,C20)-1) -> 5 | B20: =Dennis!$B$2 -> Dennis | C20: =Dennis!$G$2 -> 3 | D20: =Dennis!$J$2 -> 1 | E20: =Dennis!$L$2 -> 1 | F20: Spelare 09 | H20: Snitt tippade mål/match | I20: =IFERROR((SUM(Ricardo!I7:J110)+SUM(Janne!I7:J110)+SUM(Bosse!I7:J110)+SUM(Stina!I7:J110)+SUM(Robban!I7:J110)+SUM(Chrille!I7:J110)+SUM('John T.'!I7:J110)+SUM(Clabbe!I7:J110)+SUM(Dennis!I7:J110)+SUM(Monfors!I7:J110)+SUM('Anders D.'!I7:J110)+SUM(Evelina!I7:J110)+SUM(Nizze!I7:J110)+SUM(Sorken!I7:J110)+SUM(Peter!I7:J110)+SUM(Antonia!I7:J110)+SUM('Niklas A.'!I7:J110)+SUM('Thomas B.'!I7:J110)+SUM(Micke!I7:J110)+SUM(Robin!I7:J110)+SUM('Spelare 21'!I7:J110)+SUM('Spelare 22'!I7:J110)+SUM('Spelare 23'!I7:J110)+SUM('Spelare 24'!I7:J110)+SUM('Spelare 25'!I7:J110)+SUM('Spelare 26'!I7:J110)+SUM('Spelare 27'!I7:J110)+SUM('Spelare 28'!I7:J110)+SUM('Spelare 29'!I7:J110)+SUM('Spelare 30'!I7:J110))/(COUNT(Ricardo!I7:J110)+COUNT(Janne!I7:J110)+COUNT(Bosse!I7:J110)+COUNT(Stina!I7:J110)+COUNT(Robban!I7:J110)+COUNT(Chrille!I7:J110)+COUNT('John T.'!I7:J110)+COUNT(Clabbe!I7:J110)+COUNT(Dennis!I7:J110)+COUNT(Monfors!I7:J110)+COUNT('Anders D.'!I7:J110)+COUNT(Evelina!I7:J110)+COUNT(Nizze!I7:J110)+COUNT(Sorken!I7:J110)+COUNT(Peter!I7:J110)+COUNT(Antonia!I7:J110)+COUNT('Niklas A.'!I7:J110)+COUNT('Thomas B.'!I7:J110)+COUNT(Micke!I7:J110)+COUNT(Robin!I7:J110)+COUNT('Spelare 21'!I7:J110)+COUNT('Spelare 22'!I7:J110)+COUNT('Spelare 23'!I7:J110)+COUNT('Spelare 24'!I7:J110)+COUNT('Spelare 25'!I7:J110)+COUNT('Spelare 26'!I7:J110)+COUNT('Spelare 27'!I7:J110)+COUNT('Spelare 28'!I7:J110)+COUNT('Spelare 29'!I7:J110)+COUNT('Spelare 30'!I7:J110)/2),0) -> 1.1795673 | K20: X | L20: =COUNTIF(Ricardo!K7:K110,"X")+COUNTIF(Janne!K7:K110,"X")+COUNTIF(Bosse!K7:K110,"X")+COUNTIF(Stina!K7:K110,"X")+COUNTIF(Robban!K7:K110,"X")+COUNTIF(Chrille!K7:K110,"X")+COUNTIF('John T.'!K7:K110,"X")+COUNTIF(Clabbe!K7:K110,"X")+COUNTIF(Dennis!K7:K110,"X")+COUNTIF(Monfors!K7:K110,"X")+COUNTIF('Anders D.'!K7:K110,"X")+COUNTIF(Evelina!K7:K110,"X")+COUNTIF(Nizze!K7:K110,"X")+COUNTIF(Sorken!K7:K110,"X")+COUNTIF(Peter!K7:K110,"X")+COUNTIF(Antonia!K7:K110,"X")+COUNTIF('Niklas A.'!K7:K110,"X")+COUNTIF('Thomas B.'!K7:K110,"X")+COUNTIF(Micke!K7:K110,"X")+COUNTIF(Robin!K7:K110,"X")+COUNTIF('Spelare 21'!K7:K110,"X")+COUNTIF('Spelare 22'!K7:K110,"X")+COUNTIF('Spelare 23'!K7:K110,"X")+COUNTIF('Spelare 24'!K7:K110,"X")+COUNTIF('Spelare 25'!K7:K110,"X")+COUNTIF('Spelare 26'!K7:K110,"X")+COUNTIF('Spelare 27'!K7:K110,"X")+COUNTIF('Spelare 28'!K7:K110,"X")+COUNTIF('Spelare 29'!K7:K110,"X")+COUNTIF('Spelare 30'!K7:K110,"X") -> 537 | M20: 1 | N20: =COUNTIF(Ricardo!I7:J110,1)+COUNTIF(Janne!I7:J110,1)+COUNTIF(Bosse!I7:J110,1)+COUNTIF(Stina!I7:J110,1)+COUNTIF(Robban!I7:J110,1)+COUNTIF(Chrille!I7:J110,1)+COUNTIF('John T.'!I7:J110,1)+COUNTIF(Clabbe!I7:J110,1)+COUNTIF(Dennis!I7:J110,1)+COUNTIF(Monfors!I7:J110,1)+COUNTIF('Anders D.'!I7:J110,1)+COUNTIF(Evelina!I7:J110,1)+COUNTIF(Nizze!I7:J110,1)+COUNTIF(Sorken!I7:J110,1)+COUNTIF(Peter!I7:J110,1)+COUNTIF(Antonia!I7:J110,1)+COUNTIF('Niklas A.'!I7:J110,1)+COUNTIF('Thomas B.'!I7:J110,1)+COUNTIF(Micke!I7:J110,1)+COUNTIF(Robin!I7:J110,1)+COUNTIF('Spelare 21'!I7:J110,1)+COUNTIF('Spelare 22'!I7:J110,1)+COUNTIF('Spelare 23'!I7:J110,1)+COUNTIF('Spelare 24'!I7:J110,1)+COUNTIF('Spelare 25'!I7:J110,1)+COUNTIF('Spelare 26'!I7:J110,1)+COUNTIF('Spelare 27'!I7:J110,1)+COUNTIF('Spelare 28'!I7:J110,1)+COUNTIF('Spelare 29'!I7:J110,1)+COUNTIF('Spelare 30'!I7:J110,1) -> 1477
A21: =IF(C21="","",1+COUNTIF($C$12:$C$41,">"&C21)+COUNTIFS($C$12:C21,C21)-1) -> 11 | B21: =Monfors!$B$2 -> A. Monfors | C21: =Monfors!$G$2 -> 1 | D21: =Monfors!$J$2 -> 0 | E21: =Monfors!$L$2 -> 1 | F21: Spelare 10 | H21: Hemmatecken tippade | I21: =COUNTIF(Ricardo!K7:K110,"1")+COUNTIF(Janne!K7:K110,"1")+COUNTIF(Bosse!K7:K110,"1")+COUNTIF(Stina!K7:K110,"1")+COUNTIF(Robban!K7:K110,"1")+COUNTIF(Chrille!K7:K110,"1")+COUNTIF('John T.'!K7:K110,"1")+COUNTIF(Clabbe!K7:K110,"1")+COUNTIF(Dennis!K7:K110,"1")+COUNTIF(Monfors!K7:K110,"1")+COUNTIF('Anders D.'!K7:K110,"1")+COUNTIF(Evelina!K7:K110,"1")+COUNTIF(Nizze!K7:K110,"1")+COUNTIF(Sorken!K7:K110,"1")+COUNTIF(Peter!K7:K110,"1")+COUNTIF(Antonia!K7:K110,"1")+COUNTIF('Niklas A.'!K7:K110,"1")+COUNTIF('Thomas B.'!K7:K110,"1")+COUNTIF(Micke!K7:K110,"1")+COUNTIF(Robin!K7:K110,"1")+COUNTIF('Spelare 21'!K7:K110,"1")+COUNTIF('Spelare 22'!K7:K110,"1")+COUNTIF('Spelare 23'!K7:K110,"1")+COUNTIF('Spelare 24'!K7:K110,"1")+COUNTIF('Spelare 25'!K7:K110,"1")+COUNTIF('Spelare 26'!K7:K110,"1")+COUNTIF('Spelare 27'!K7:K110,"1")+COUNTIF('Spelare 28'!K7:K110,"1")+COUNTIF('Spelare 29'!K7:K110,"1")+COUNTIF('Spelare 30'!K7:K110,"1") -> 961 | K21: 2 | L21: =COUNTIF(Ricardo!K7:K110,"2")+COUNTIF(Janne!K7:K110,"2")+COUNTIF(Bosse!K7:K110,"2")+COUNTIF(Stina!K7:K110,"2")+COUNTIF(Robban!K7:K110,"2")+COUNTIF(Chrille!K7:K110,"2")+COUNTIF('John T.'!K7:K110,"2")+COUNTIF(Clabbe!K7:K110,"2")+COUNTIF(Dennis!K7:K110,"2")+COUNTIF(Monfors!K7:K110,"2")+COUNTIF('Anders D.'!K7:K110,"2")+COUNTIF(Evelina!K7:K110,"2")+COUNTIF(Nizze!K7:K110,"2")+COUNTIF(Sorken!K7:K110,"2")+COUNTIF(Peter!K7:K110,"2")+COUNTIF(Antonia!K7:K110,"2")+COUNTIF('Niklas A.'!K7:K110,"2")+COUNTIF('Thomas B.'!K7:K110,"2")+COUNTIF(Micke!K7:K110,"2")+COUNTIF(Robin!K7:K110,"2")+COUNTIF('Spelare 21'!K7:K110,"2")+COUNTIF('Spelare 22'!K7:K110,"2")+COUNTIF('Spelare 23'!K7:K110,"2")+COUNTIF('Spelare 24'!K7:K110,"2")+COUNTIF('Spelare 25'!K7:K110,"2")+COUNTIF('Spelare 26'!K7:K110,"2")+COUNTIF('Spelare 27'!K7:K110,"2")+COUNTIF('Spelare 28'!K7:K110,"2")+COUNTIF('Spelare 29'!K7:K110,"2")+COUNTIF('Spelare 30'!K7:K110,"2") -> 582 | M21: 2 | N21: =COUNTIF(Ricardo!I7:J110,2)+COUNTIF(Janne!I7:J110,2)+COUNTIF(Bosse!I7:J110,2)+COUNTIF(Stina!I7:J110,2)+COUNTIF(Robban!I7:J110,2)+COUNTIF(Chrille!I7:J110,2)+COUNTIF('John T.'!I7:J110,2)+COUNTIF(Clabbe!I7:J110,2)+COUNTIF(Dennis!I7:J110,2)+COUNTIF(Monfors!I7:J110,2)+COUNTIF('Anders D.'!I7:J110,2)+COUNTIF(Evelina!I7:J110,2)+COUNTIF(Nizze!I7:J110,2)+COUNTIF(Sorken!I7:J110,2)+COUNTIF(Peter!I7:J110,2)+COUNTIF(Antonia!I7:J110,2)+COUNTIF('Niklas A.'!I7:J110,2)+COUNTIF('Thomas B.'!I7:J110,2)+COUNTIF(Micke!I7:J110,2)+COUNTIF(Robin!I7:J110,2)+COUNTIF('Spelare 21'!I7:J110,2)+COUNTIF('Spelare 22'!I7:J110,2)+COUNTIF('Spelare 23'!I7:J110,2)+COUNTIF('Spelare 24'!I7:J110,2)+COUNTIF('Spelare 25'!I7:J110,2)+COUNTIF('Spelare 26'!I7:J110,2)+COUNTIF('Spelare 27'!I7:J110,2)+COUNTIF('Spelare 28'!I7:J110,2)+COUNTIF('Spelare 29'!I7:J110,2)+COUNTIF('Spelare 30'!I7:J110,2) -> 1120
A22: =IF(C22="","",1+COUNTIF($C$12:$C$41,">"&C22)+COUNTIFS($C$12:C22,C22)-1) -> 12 | B22: ='Anders D.'!$B$2 -> Anders D. | C22: ='Anders D.'!$G$2 -> 1 | D22: ='Anders D.'!$J$2 -> 0 | E22: ='Anders D.'!$L$2 -> 1 | F22: Spelare 11 | H22: Kryss tippade | I22: =COUNTIF(Ricardo!K7:K110,"X")+COUNTIF(Janne!K7:K110,"X")+COUNTIF(Bosse!K7:K110,"X")+COUNTIF(Stina!K7:K110,"X")+COUNTIF(Robban!K7:K110,"X")+COUNTIF(Chrille!K7:K110,"X")+COUNTIF('John T.'!K7:K110,"X")+COUNTIF(Clabbe!K7:K110,"X")+COUNTIF(Dennis!K7:K110,"X")+COUNTIF(Monfors!K7:K110,"X")+COUNTIF('Anders D.'!K7:K110,"X")+COUNTIF(Evelina!K7:K110,"X")+COUNTIF(Nizze!K7:K110,"X")+COUNTIF(Sorken!K7:K110,"X")+COUNTIF(Peter!K7:K110,"X")+COUNTIF(Antonia!K7:K110,"X")+COUNTIF('Niklas A.'!K7:K110,"X")+COUNTIF('Thomas B.'!K7:K110,"X")+COUNTIF(Micke!K7:K110,"X")+COUNTIF(Robin!K7:K110,"X")+COUNTIF('Spelare 21'!K7:K110,"X")+COUNTIF('Spelare 22'!K7:K110,"X")+COUNTIF('Spelare 23'!K7:K110,"X")+COUNTIF('Spelare 24'!K7:K110,"X")+COUNTIF('Spelare 25'!K7:K110,"X")+COUNTIF('Spelare 26'!K7:K110,"X")+COUNTIF('Spelare 27'!K7:K110,"X")+COUNTIF('Spelare 28'!K7:K110,"X")+COUNTIF('Spelare 29'!K7:K110,"X")+COUNTIF('Spelare 30'!K7:K110,"X") -> 537 | M22: 3 | N22: =COUNTIF(Ricardo!I7:J110,3)+COUNTIF(Janne!I7:J110,3)+COUNTIF(Bosse!I7:J110,3)+COUNTIF(Stina!I7:J110,3)+COUNTIF(Robban!I7:J110,3)+COUNTIF(Chrille!I7:J110,3)+COUNTIF('John T.'!I7:J110,3)+COUNTIF(Clabbe!I7:J110,3)+COUNTIF(Dennis!I7:J110,3)+COUNTIF(Monfors!I7:J110,3)+COUNTIF('Anders D.'!I7:J110,3)+COUNTIF(Evelina!I7:J110,3)+COUNTIF(Nizze!I7:J110,3)+COUNTIF(Sorken!I7:J110,3)+COUNTIF(Peter!I7:J110,3)+COUNTIF(Antonia!I7:J110,3)+COUNTIF('Niklas A.'!I7:J110,3)+COUNTIF('Thomas B.'!I7:J110,3)+COUNTIF(Micke!I7:J110,3)+COUNTIF(Robin!I7:J110,3)+COUNTIF('Spelare 21'!I7:J110,3)+COUNTIF('Spelare 22'!I7:J110,3)+COUNTIF('Spelare 23'!I7:J110,3)+COUNTIF('Spelare 24'!I7:J110,3)+COUNTIF('Spelare 25'!I7:J110,3)+COUNTIF('Spelare 26'!I7:J110,3)+COUNTIF('Spelare 27'!I7:J110,3)+COUNTIF('Spelare 28'!I7:J110,3)+COUNTIF('Spelare 29'!I7:J110,3)+COUNTIF('Spelare 30'!I7:J110,3) -> 303
A23: =IF(C23="","",1+COUNTIF($C$12:$C$41,">"&C23)+COUNTIFS($C$12:C23,C23)-1) -> 13 | B23: =Evelina!$B$2 -> Eve | C23: =Evelina!$G$2 -> 1 | D23: =Evelina!$J$2 -> 0 | E23: =Evelina!$L$2 -> 1 | F23: Spelare 12 | H23: Bortatecken tippade | I23: =COUNTIF(Ricardo!K7:K110,"2")+COUNTIF(Janne!K7:K110,"2")+COUNTIF(Bosse!K7:K110,"2")+COUNTIF(Stina!K7:K110,"2")+COUNTIF(Robban!K7:K110,"2")+COUNTIF(Chrille!K7:K110,"2")+COUNTIF('John T.'!K7:K110,"2")+COUNTIF(Clabbe!K7:K110,"2")+COUNTIF(Dennis!K7:K110,"2")+COUNTIF(Monfors!K7:K110,"2")+COUNTIF('Anders D.'!K7:K110,"2")+COUNTIF(Evelina!K7:K110,"2")+COUNTIF(Nizze!K7:K110,"2")+COUNTIF(Sorken!K7:K110,"2")+COUNTIF(Peter!K7:K110,"2")+COUNTIF(Antonia!K7:K110,"2")+COUNTIF('Niklas A.'!K7:K110,"2")+COUNTIF('Thomas B.'!K7:K110,"2")+COUNTIF(Micke!K7:K110,"2")+COUNTIF(Robin!K7:K110,"2")+COUNTIF('Spelare 21'!K7:K110,"2")+COUNTIF('Spelare 22'!K7:K110,"2")+COUNTIF('Spelare 23'!K7:K110,"2")+COUNTIF('Spelare 24'!K7:K110,"2")+COUNTIF('Spelare 25'!K7:K110,"2")+COUNTIF('Spelare 26'!K7:K110,"2")+COUNTIF('Spelare 27'!K7:K110,"2")+COUNTIF('Spelare 28'!K7:K110,"2")+COUNTIF('Spelare 29'!K7:K110,"2")+COUNTIF('Spelare 30'!K7:K110,"2") -> 582 | M23: 4+ | N23: =COUNTIF(Ricardo!I7:J110,">=4")+COUNTIF(Janne!I7:J110,">=4")+COUNTIF(Bosse!I7:J110,">=4")+COUNTIF(Stina!I7:J110,">=4")+COUNTIF(Robban!I7:J110,">=4")+COUNTIF(Chrille!I7:J110,">=4")+COUNTIF('John T.'!I7:J110,">=4")+COUNTIF(Clabbe!I7:J110,">=4")+COUNTIF(Dennis!I7:J110,">=4")+COUNTIF(Monfors!I7:J110,">=4")+COUNTIF('Anders D.'!I7:J110,">=4")+COUNTIF(Evelina!I7:J110,">=4")+COUNTIF(Nizze!I7:J110,">=4")+COUNTIF(Sorken!I7:J110,">=4")+COUNTIF(Peter!I7:J110,">=4")+COUNTIF(Antonia!I7:J110,">=4")+COUNTIF('Niklas A.'!I7:J110,">=4")+COUNTIF('Thomas B.'!I7:J110,">=4")+COUNTIF(Micke!I7:J110,">=4")+COUNTIF(Robin!I7:J110,">=4")+COUNTIF('Spelare 21'!I7:J110,">=4")+COUNTIF('Spelare 22'!I7:J110,">=4")+COUNTIF('Spelare 23'!I7:J110,">=4")+COUNTIF('Spelare 24'!I7:J110,">=4")+COUNTIF('Spelare 25'!I7:J110,">=4")+COUNTIF('Spelare 26'!I7:J110,">=4")+COUNTIF('Spelare 27'!I7:J110,">=4")+COUNTIF('Spelare 28'!I7:J110,">=4")+COUNTIF('Spelare 29'!I7:J110,">=4")+COUNTIF('Spelare 30'!I7:J110,">=4") -> 65
A24: =IF(C24="","",1+COUNTIF($C$12:$C$41,">"&C24)+COUNTIFS($C$12:C24,C24)-1) -> 6 | B24: =Nizze!$B$2 -> Nizze | C24: =Nizze!$G$2 -> 3 | D24: =Nizze!$J$2 -> 1 | E24: =Nizze!$L$2 -> 1 | F24: Spelare 13
A25: =IF(C25="","",1+COUNTIF($C$12:$C$41,">"&C25)+COUNTIFS($C$12:C25,C25)-1) -> 20 | B25: =Sorken!$B$2 -> Sorken | C25: =Sorken!$G$2 -> 0 | D25: =Sorken!$J$2 -> 0 | E25: =Sorken!$L$2 -> 0 | F25: Spelare 14
A26: =IF(C26="","",1+COUNTIF($C$12:$C$41,">"&C26)+COUNTIFS($C$12:C26,C26)-1) -> 14 | B26: =Peter!$B$2 -> Peter | C26: =Peter!$G$2 -> 1 | D26: =Peter!$J$2 -> 0 | E26: =Peter!$L$2 -> 1 | F26: Spelare 15
A27: =IF(C27="","",1+COUNTIF($C$12:$C$41,">"&C27)+COUNTIFS($C$12:C27,C27)-1) -> 15 | B27: =Antonia!$B$2 -> Antonia | C27: =Antonia!$G$2 -> 1 | D27: =Antonia!$J$2 -> 0 | E27: =Antonia!$L$2 -> 1 | F27: Spelare 16
A28: =IF(C28="","",1+COUNTIF($C$12:$C$41,">"&C28)+COUNTIFS($C$12:C28,C28)-1) -> 16 | B28: ='Niklas A.'!$B$2 -> Niklas A. | C28: ='Niklas A.'!$G$2 -> 1 | D28: ='Niklas A.'!$J$2 -> 0 | E28: ='Niklas A.'!$L$2 -> 1 | F28: Spelare 17
A29: =IF(C29="","",1+COUNTIF($C$12:$C$41,">"&C29)+COUNTIFS($C$12:C29,C29)-1) -> 17 | B29: ='Thomas B.'!$B$2 -> Thomas B. | C29: ='Thomas B.'!$G$2 -> 1 | D29: ='Thomas B.'!$J$2 -> 0 | E29: ='Thomas B.'!$L$2 -> 1 | F29: Spelare 18
A30: =IF(C30="","",1+COUNTIF($C$12:$C$41,">"&C30)+COUNTIFS($C$12:C30,C30)-1) -> 18 | B30: =Micke!$B$2 -> Micke | C30: =Micke!$G$2 -> 1 | D30: =Micke!$J$2 -> 0 | E30: =Micke!$L$2 -> 1 | F30: Spelare 19
A31: =IF(C31="","",1+COUNTIF($C$12:$C$41,">"&C31)+COUNTIFS($C$12:C31,C31)-1) -> 19 | B31: =Robin!$B$2 -> Robin | C31: =Robin!$G$2 -> 1 | D31: =Robin!$J$2 -> 0 | E31: =Robin!$L$2 -> 1 | F31: Spelare 20
A32: =IF(C32="","",1+COUNTIF($C$12:$C$41,">"&C32)+COUNTIFS($C$12:C32,C32)-1) -> 21 | B32: ='Spelare 21'!$B$2 -> Spelare 21 | C32: ='Spelare 21'!$G$2 -> 0 | D32: ='Spelare 21'!$J$2 -> 0 | E32: ='Spelare 21'!$L$2 -> 0 | F32: Spelare 21
A33: =IF(C33="","",1+COUNTIF($C$12:$C$41,">"&C33)+COUNTIFS($C$12:C33,C33)-1) -> 22 | B33: ='Spelare 22'!$B$2 -> Spelare 22 | C33: ='Spelare 22'!$G$2 -> 0 | D33: ='Spelare 22'!$J$2 -> 0 | E33: ='Spelare 22'!$L$2 -> 0 | F33: Spelare 22
A34: =IF(C34="","",1+COUNTIF($C$12:$C$41,">"&C34)+COUNTIFS($C$12:C34,C34)-1) -> 23 | B34: ='Spelare 23'!$B$2 -> Spelare 23 | C34: ='Spelare 23'!$G$2 -> 0 | D34: ='Spelare 23'!$J$2 -> 0 | E34: ='Spelare 23'!$L$2 -> 0 | F34: Spelare 23
A35: =IF(C35="","",1+COUNTIF($C$12:$C$41,">"&C35)+COUNTIFS($C$12:C35,C35)-1) -> 24 | B35: ='Spelare 24'!$B$2 -> Spelare 24 | C35: ='Spelare 24'!$G$2 -> 0 | D35: ='Spelare 24'!$J$2 -> 0 | E35: ='Spelare 24'!$L$2 -> 0 | F35: Spelare 24
A36: =IF(C36="","",1+COUNTIF($C$12:$C$41,">"&C36)+COUNTIFS($C$12:C36,C36)-1) -> 25 | B36: ='Spelare 25'!$B$2 -> Spelare 25 | C36: ='Spelare 25'!$G$2 -> 0 | D36: ='Spelare 25'!$J$2 -> 0 | E36: ='Spelare 25'!$L$2 -> 0 | F36: Spelare 25
A37: =IF(C37="","",1+COUNTIF($C$12:$C$41,">"&C37)+COUNTIFS($C$12:C37,C37)-1) -> 26 | B37: ='Spelare 26'!$B$2 -> Spelare 26 | C37: ='Spelare 26'!$G$2 -> 0 | D37: ='Spelare 26'!$J$2 -> 0 | E37: ='Spelare 26'!$L$2 -> 0 | F37: Spelare 26
A38: =IF(C38="","",1+COUNTIF($C$12:$C$41,">"&C38)+COUNTIFS($C$12:C38,C38)-1) -> 27 | B38: ='Spelare 27'!$B$2 -> Spelare 27 | C38: ='Spelare 27'!$G$2 -> 0 | D38: ='Spelare 27'!$J$2 -> 0 | E38: ='Spelare 27'!$L$2 -> 0 | F38: Spelare 27
A39: =IF(C39="","",1+COUNTIF($C$12:$C$41,">"&C39)+COUNTIFS($C$12:C39,C39)-1) -> 28 | B39: ='Spelare 28'!$B$2 -> Spelare 28 | C39: ='Spelare 28'!$G$2 -> 0 | D39: ='Spelare 28'!$J$2 -> 0 | E39: ='Spelare 28'!$L$2 -> 0 | F39: Spelare 28
A40: =IF(C40="","",1+COUNTIF($C$12:$C$41,">"&C40)+COUNTIFS($C$12:C40,C40)-1) -> 29 | B40: ='Spelare 29'!$B$2 -> Spelare 29 | C40: ='Spelare 29'!$G$2 -> 0 | D40: ='Spelare 29'!$J$2 -> 0 | E40: ='Spelare 29'!$L$2 -> 0 | F40: Spelare 29
A41: =IF(C41="","",1+COUNTIF($C$12:$C$41,">"&C41)+COUNTIFS($C$12:C41,C41)-1) -> 30 | B41: ='Spelare 30'!$B$2 -> Spelare 30 | C41: ='Spelare 30'!$G$2 -> 0 | D41: ='Spelare 30'!$J$2 -> 0 | E41: ='Spelare 30'!$L$2 -> 0 | F41: Spelare 30

Sheet Blad1

Sheet Blad2

Sheet Matchschema
A1: Nr | B1: Fas | C1: Grupp | D1: Datum Sverige | E1: Tid Sverige | F1: Datum ET | G1: Tid ET | H1: Hemmalag | I1: Bortalag | J1: Arena | K1: Facit H | L1: Facit B | M1: Facit tecken | N1: Källa
A2: 1 | B2: Gruppspel | C2: A | D2: 46184.875 | E2: 21:00 | F2: 46184.625 | G2: 15:00 | H2: Mexico | I2: South Africa | J2: Estadio Azteca, Mexico City | K2: 2 | L2: 0 | M2: =IF(OR(K2="",L2=""),"",IF(K2>L2,"1",IF(K2=L2,"X","2"))) -> 1 | N2: https://www.fifa.com/en/tournaments/mens/worldcup/canadamexicousa2026/articles/match-schedule-fixtures-results-teams-stadiums
A3: 2 | B3: Gruppspel | C3: A | D3: 46185.167 | E3: 04:00 | F3: 46184.917 | G3: 22:00 | H3: South Korea | I3: Czechia | J3: Estadio Akron, Zapopan | M3: =IF(OR(K3="",L3=""),"",IF(K3>L3,"1",IF(K3=L3,"X","2"))) | N3: https://www.fifa.com/en/tournaments/mens/worldcup/canadamexicousa2026/articles/match-schedule-fixtures-results-teams-stadiums
A4: 3 | B4: Gruppspel | C4: B | D4: 46185.875 | E4: 21:00 | F4: 46185.625 | G4: 15:00 | H4: Canada | I4: Bosnia & Herzegovina | J4: BMO Field, Toronto | M4: =IF(OR(K4="",L4=""),"",IF(K4>L4,"1",IF(K4=L4,"X","2"))) | N4: https://www.fifa.com/en/tournaments/mens/worldcup/canadamexicousa2026/articles/match-schedule-fixtures-results-teams-stadiums
A5: 4 | B5: Gruppspel | C5: D | D5: 46186.125 | E5: 03:00 | F5: 46185.875 | G5: 21:00 | H5: USA | I5: Paraguay | J5: SoFi Stadium, Inglewood | M5: =IF(OR(K5="",L5=""),"",IF(K5>L5,"1",IF(K5=L5,"X","2"))) | N5: https://www.fifa.com/en/tournaments/mens/worldcup/canadamexicousa2026/articles/match-schedule-fixtures-results-teams-stadiums
A6: 5 | B6: Gruppspel | C6: B | D6: 46186.875 | E6: 21:00 | F6: 46186.625 | G6: 15:00 | H6: Qatar | I6: Switzerland | J6: Levi’s Stadium, Santa Clara | M6: =IF(OR(K6="",L6=""),"",IF(K6>L6,"1",IF(K6=L6,"X","2"))) | N6: https://www.fifa.com/en/tournaments/mens/worldcup/canadamexicousa2026/articles/match-schedule-fixtures-results-teams-stadiums
A7: 6 | B7: Gruppspel | C7: C | D7: 46187 | E7: 00:00 | F7: 46186.75 | G7: 18:00 | H7: Brazil | I7: Morocco | J7: MetLife Stadium, East Rutherford | M7: =IF(OR(K7="",L7=""),"",IF(K7>L7,"1",IF(K7=L7,"X","2"))) | N7: https://www.fifa.com/en/tournaments/mens/worldcup/canadamexicousa2026/articles/match-schedule-fixtures-results-teams-stadiums
A8: 7 | B8: Gruppspel | C8: C | D8: 46187.125 | E8: 03:00 | F8: 46186.875 | G8: 21:00 | H8: Haiti | I8: Scotland | J8: Gillette Stadium, Foxborough | M8: =IF(OR(K8="",L8=""),"",IF(K8>L8,"1",IF(K8=L8,"X","2"))) | N8: https://www.fifa.com/en/tournaments/mens/worldcup/canadamexicousa2026/articles/match-schedule-fixtures-results-teams-stadiums
A9: 8 | B9: Gruppspel | C9: D | D9: 46187.25 | E9: 06:00 | F9: 46187 | G9: 00:00 | H9: Australia | I9: Türkiye | J9: BC Place, Vancouver | M9: =IF(OR(K9="",L9=""),"",IF(K9>L9,"1",IF(K9=L9,"X","2"))) | N9: https://www.fifa.com/en/tournaments/mens/worldcup/canadamexicousa2026/articles/match-schedule-fixtures-results-teams-stadiums
A10: 9 | B10: Gruppspel | C10: E | D10: 46187.792 | E10: 19:00 | F10: 46187.542 | G10: 13:00 | H10: Germany | I10: Curaçao | J10: NRG Stadium, Houston | M10: =IF(OR(K10="",L10=""),"",IF(K10>L10,"1",IF(K10=L10,"X","2"))) | N10: https://www.fifa.com/en/tournaments/mens/worldcup/canadamexicousa2026/articles/match-schedule-fixtures-results-teams-stadiums
A11: 10 | B11: Gruppspel | C11: F | D11: 46187.917 | E11: 22:00 | F11: 46187.667 | G11: 16:00 | H11: Netherlands | I11: Japan | J11: AT&T Stadium, Arlington | M11: =IF(OR(K11="",L11=""),"",IF(K11>L11,"1",IF(K11=L11,"X","2"))) | N11: https://www.fifa.com/en/tournaments/mens/worldcup/canadamexicousa2026/articles/match-schedule-fixtures-results-teams-stadiums
A12: 11 | B12: Gruppspel | C12: E | D12: 46188.042 | E12: 01:00 | F12: 46187.792 | G12: 19:00 | H12: Ivory Coast | I12: Ecuador | J12: Lincoln Financial Field, Philadelphia | M12: =IF(OR(K12="",L12=""),"",IF(K12>L12,"1",IF(K12=L12,"X","2"))) | N12: https://www.fifa.com/en/tournaments/mens/worldcup/canadamexicousa2026/articles/match-schedule-fixtures-results-teams-stadiums
A13: 12 | B13: Gruppspel | C13: F | D13: 46188.167 | E13: 04:00 | F13: 46187.917 | G13: 22:00 | H13: Sweden | I13: Tunisia | J13: Estadio BBVA, Monterrey | M13: =IF(OR(K13="",L13=""),"",IF(K13>L13,"1",IF(K13=L13,"X","2"))) | N13: https://www.fifa.com/en/tournaments/mens/worldcup/canadamexicousa2026/articles/match-schedule-fixtures-results-teams-stadiums
A14: 13 | B14: Gruppspel | C14: H | D14: 46188.75 | E14: 18:00 | F14: 46188.5 | G14: 12:00 | H14: Spain | I14: Cape Verde | J14: Mercedes-Benz Stadium, Atlanta | M14: =IF(OR(K14="",L14=""),"",IF(K14>L14,"1",IF(K14=L14,"X","2"))) | N14: https://www.fifa.com/en/tournaments/mens/worldcup/canadamexicousa2026/articles/match-schedule-fixtures-results-teams-stadiums
... A73: 72 | B73: Gruppspel | C73: J | D73: 46201.167 | E73: 04:00 | F73: 46200.917 | G73: 22:00 | H73: Jordan | I73: Argentina | J73: AT&T Stadium, Arlington | M73: =IF(OR(K73="",L73=""),"",IF(K73>L73,"1",IF(K73=L73,"X","2"))) | N73: https://www.fifa.com/en/tournaments/mens/worldcup/canadamexicousa2026/articles/match-schedule-fixtures-results-teams-stadiums
A74: 73 | B74: 32-delsfinal | D74: 46201.875 | E74: 21:00 | F74: 46201.625 | G74: 15:00 | H74: Runner-up A | I74: Runner-up B | J74: SoFi Stadium, Inglewood | M74: =IF(OR(K74="",L74=""),"",IF(K74>L74,"1",IF(K74=L74,"X","2"))) | N74: https://www.fifa.com/en/tournaments/mens/worldcup/canadamexicousa2026/articles/match-schedule-fixtures-results-teams-stadiums
A75: 74 | B75: 32-delsfinal | D75: 46202.792 | E75: 19:00 | F75: 46202.542 | G75: 13:00 | H75: Winner C | I75: Runner-up F | J75: NRG Stadium, Houston | M75: =IF(OR(K75="",L75=""),"",IF(K75>L75,"1",IF(K75=L75,"X","2"))) | N75: https://www.fifa.com/en/tournaments/mens/worldcup/canadamexicousa2026/articles/match-schedule-fixtures-results-teams-stadiums
A76: 75 | B76: 32-delsfinal | D76: 46202.938 | E76: 22:30 | F76: 46202.688 | G76: 16:30 | H76: Winner E | I76: Best 3rd (A/B/C/D/F) | J76: Gillette Stadium, Foxborough | M76: =IF(OR(K76="",L76=""),"",IF(K76>L76,"1",IF(K76=L76,"X","2"))) | N76: https://www.fifa.com/en/tournaments/mens/worldcup/canadamexicousa2026/articles/match-schedule-fixtures-results-teams-stadiums
A77: 76 | B77: 32-delsfinal | D77: 46203.125 | E77: 03:00 | F77: 46202.875 | G77: 21:00 | H77: Winner F | I77: Runner-up C | J77: Estadio BBVA, Monterrey | M77: =IF(OR(K77="",L77=""),"",IF(K77>L77,"1",IF(K77=L77,"X","2"))) | N77: https://www.fifa.com/en/tournaments/mens/worldcup/canadamexicousa2026/articles/match-schedule-fixtures-results-teams-stadiums
A78: 77 | B78: 32-delsfinal | D78: 46203.792 | E78: 19:00 | F78: 46203.542 | G78: 13:00 | H78: Runner-up E | I78: Runner-up I | J78: AT&T Stadium, Arlington | M78: =IF(OR(K78="",L78=""),"",IF(K78>L78,"1",IF(K78=L78,"X","2"))) | N78: https://www.fifa.com/en/tournaments/mens/worldcup/canadamexicousa2026/articles/match-schedule-fixtures-results-teams-stadiums
A79: 78 | B79: 32-delsfinal | D79: 46203.958 | E79: 23:00 | F79: 46203.708 | G79: 17:00 | H79: Winner I | I79: Best 3rd (C/D/F/G/H) | J79: MetLife Stadium, East Rutherford | M79: =IF(OR(K79="",L79=""),"",IF(K79>L79,"1",IF(K79=L79,"X","2"))) | N79: https://www.fifa.com/en/tournaments/mens/worldcup/canadamexicousa2026/articles/match-schedule-fixtures-results-teams-stadiums
A80: 79 | B80: 32-delsfinal | D80: 46204.125 | E80: 03:00 | F80: 46203.875 | G80: 21:00 | H80: Winner A | I80: Best 3rd (C/E/F/H/I) | J80: Estadio Azteca, Mexico City | M80: =IF(OR(K80="",L80=""),"",IF(K80>L80,"1",IF(K80=L80,"X","2"))) | N80: https://www.fifa.com/en/tournaments/mens/worldcup/canadamexicousa2026/articles/match-schedule-fixtures-results-teams-stadiums
A81: 80 | B81: 32-delsfinal | D81: 46204.75 | E81: 18:00 | F81: 46204.5 | G81: 12:00 | H81: Winner L | I81: Best 3rd (E/H/I/J/K) | J81: Mercedes-Benz Stadium, Atlanta | M81: =IF(OR(K81="",L81=""),"",IF(K81>L81,"1",IF(K81=L81,"X","2"))) | N81: https://www.fifa.com/en/tournaments/mens/worldcup/canadamexicousa2026/articles/match-schedule-fixtures-results-teams-stadiums
A82: 81 | B82: 32-delsfinal | D82: 46204.917 | E82: 22:00 | F82: 46204.667 | G82: 16:00 | H82: Winner G | I82: Best 3rd (A/E/H/I/J) | J82: Lumen Field, Seattle | M82: =IF(OR(K82="",L82=""),"",IF(K82>L82,"1",IF(K82=L82,"X","2"))) | N82: https://www.fifa.com/en/tournaments/mens/worldcup/canadamexicousa2026/articles/match-schedule-fixtures-results-teams-stadiums
A83: 82 | B83: 32-delsfinal | D83: 46205.083 | E83: 02:00 | F83: 46204.833 | G83: 20:00 | H83: Winner D | I83: Best 3rd (B/E/F/I/J) | J83: Levi’s Stadium, Santa Clara | M83: =IF(OR(K83="",L83=""),"",IF(K83>L83,"1",IF(K83=L83,"X","2"))) | N83: https://www.fifa.com/en/tournaments/mens/worldcup/canadamexicousa2026/articles/match-schedule-fixtures-results-teams-stadiums
A84: 83 | B84: 32-delsfinal | D84: 46205.875 | E84: 21:00 | F84: 46205.625 | G84: 15:00 | H84: Winner H | I84: Runner-up J | J84: SoFi Stadium, Inglewood | M84: =IF(OR(K84="",L84=""),"",IF(K84>L84,"1",IF(K84=L84,"X","2"))) | N84: https://www.fifa.com/en/tournaments/mens/worldcup/canadamexicousa2026/articles/match-schedule-fixtures-results-teams-stadiums
A85: 84 | B85: 32-delsfinal | D85: 46206.042 | E85: 01:00 | F85: 46205.792 | G85: 19:00 | H85: Runner-up K | I85: Runner-up L | J85: BMO Field, Toronto | M85: =IF(OR(K85="",L85=""),"",IF(K85>L85,"1",IF(K85=L85,"X","2"))) | N85: https://www.fifa.com/en/tournaments/mens/worldcup/canadamexicousa2026/articles/match-schedule-fixtures-results-teams-stadiums
... A105: 104 | B105: Final | D105: 46222.875 | E105: 21:00 | F105: 46222.625 | G105: 15:00 | H105: Winner Match 101 | I105: Winner Match 102 | J105: MetLife Stadium, East Rutherford, NJ | M105: =IF(OR(K105="",L105=""),"",IF(K105>L105,"1",IF(K105=L105,"X","2"))) | N105: https://www.fifa.com/en/tournaments/mens/worldcup/canadamexicousa2026/articles/match-schedule-fixtures-results-teams-stadiums

Sheet Regler
A1: VM-tips 2026 – regler och källor
A3: Inställning | B3: Värde
A4: Poäng för exakt resultat | B4: 3
A5: Poäng för rätt tecken (1/X/2) | B5: 1
A6: Antal deltagare | B6: 30
A7: Antal matcher | B7: 104
A9: Så används filen
A10: 1. Gå till varje flik Spelare 01–30 och skriv deltagarens namn i cell B2.
A11: 2. Deltagaren fyller i tippade mål för hemmalag och bortalag. Tipptecken räknas automatiskt.
A12: 3. När matcherna spelats fyller admin facit i Matchschema, kolumn K–L.
A13: 4. Poängen uppdateras automatiskt på spelarnas flikar och i Startsida.
A14: 5. Ändra poängmodellen i cell B4–B5 här om ni vill ha andra regler.
A15: Tips: Skydda gärna Matchschema och Startsida om ni delar filen, så att endast personflikarna fylls i.
A16: Källor | B16: https://www.fifa.com/en/tournaments/mens/worldcup/canadamexicousa2026/articles/match-schedule-fixtures-results-teams-stadiums
B17: https://worldcupwiki.com/schedule/

Sheet Ricardo
A1: VM-tips 2026 – personlig tippflik
A2: Namn: | B2: Ricardo | F2: Totalpoäng | G2: =SUM(L7:L110) -> 3 | I2: Exakta | J2: =SUMPRODUCT(--(I7:I110=Matchschema!$K$2:$K$105),--(J7:J110=Matchschema!$L$2:$L$105),--(Matchschema!$K$2:$K$105<>"")) -> 1 | K2: Rätt tecken | L2: =SUMPRODUCT(--(K7:K110=Matchschema!$M$2:$M$105),--(Matchschema!$M$2:$M$105<>"")) -> 1
A6: Nr | B6: Fas | C6: Grupp | D6: Datum SE | E6: Tid SE | F6: Hemmalag | G6: Bortalag | H6: Arena | I6: Tip H | J6: Tip B | K6: Tipp | L6: Poäng | M6: Kommentar
A7: =Matchschema!A2 -> 1 | B7: =Matchschema!B2 -> Gruppspel | C7: =Matchschema!C2 -> A | D7: =Matchschema!D2 -> 46184.875 | E7: =Matchschema!E2 -> 21:00 | F7: =Matchschema!H2 -> Mexico | G7: =Matchschema!I2 -> South Africa | H7: =Matchschema!J2 -> Estadio Azteca, Mexico City | I7: 2 | J7: 0 | K7: =IF(OR(I7="",J7=""),"",IF(I7>J7,"1",IF(I7=J7,"X","2"))) -> 1 | L7: =IF(Matchschema!$K2="","",IF(AND(I7=Matchschema!$K2,J7=Matchschema!$L2),Regler!$B$4,IF(K7=Matchschema!$M2,Regler!$B$5,0))) -> 3
A8: =Matchschema!A3 -> 2 | B8: =Matchschema!B3 -> Gruppspel | C8: =Matchschema!C3 -> A | D8: =Matchschema!D3 -> 46185.167 | E8: =Matchschema!E3 -> 04:00 | F8: =Matchschema!H3 -> South Korea | G8: =Matchschema!I3 -> Czechia | H8: =Matchschema!J3 -> Estadio Akron, Zapopan | I8: 1 | J8: 1 | K8: =IF(OR(I8="",J8=""),"",IF(I8>J8,"1",IF(I8=J8,"X","2"))) -> X | L8: =IF(Matchschema!$K3="","",IF(AND(I8=Matchschema!$K3,J8=Matchschema!$L3),Regler!$B$4,IF(K8=Matchschema!$M3,Regler!$B$5,0)))
A9: =Matchschema!A4 -> 3 | B9: =Matchschema!B4 -> Gruppspel | C9: =Matchschema!C4 -> B | D9: =Matchschema!D4 -> 46185.875 | E9: =Matchschema!E4 -> 21:00 | F9: =Matchschema!H4 -> Canada | G9: =Matchschema!I4 -> Bosnia & Herzegovina | H9: =Matchschema!J4 -> BMO Field, Toronto | I9: 0 | J9: 1 | K9: =IF(OR(I9="",J9=""),"",IF(I9>J9,"1",IF(I9=J9,"X","2"))) -> 2 | L9: =IF(Matchschema!$K4="","",IF(AND(I9=Matchschema!$K4,J9=Matchschema!$L4),Regler!$B$4,IF(K9=Matchschema!$M4,Regler!$B$5,0)))
A10: =Matchschema!A5 -> 4 | B10: =Matchschema!B5 -> Gruppspel | C10: =Matchschema!C5 -> D | D10: =Matchschema!D5 -> 46186.125 | E10: =Matchschema!E5 -> 03:00 | F10: =Matchschema!H5 -> USA | G10: =Matchschema!I5 -> Paraguay | H10: =Matchschema!J5 -> SoFi Stadium, Inglewood | I10: 2 | J10: 2 | K10: =IF(OR(I10="",J10=""),"",IF(I10>J10,"1",IF(I10=J10,"X","2"))) -> X | L10: =IF(Matchschema!$K5="","",IF(AND(I10=Matchschema!$K5,J10=Matchschema!$L5),Regler!$B$4,IF(K10=Matchschema!$M5,Regler!$B$5,0)))
A11: =Matchschema!A6 -> 5 | B11: =Matchschema!B6 -> Gruppspel | C11: =Matchschema!C6 -> B | D11: =Matchschema!D6 -> 46186.875 | E11: =Matchschema!E6 -> 21:00 | F11: =Matchschema!H6 -> Qatar | G11: =Matchschema!I6 -> Switzerland | H11: =Matchschema!J6 -> Levi’s Stadium, Santa Clara | I11: 0 | J11: 3 | K11: =IF(OR(I11="",J11=""),"",IF(I11>J11,"1",IF(I11=J11,"X","2"))) -> 2 | L11: =IF(Matchschema!$K6="","",IF(AND(I11=Matchschema!$K6,J11=Matchschema!$L6),Regler!$B$4,IF(K11=Matchschema!$M6,Regler!$B$5,0)))
A12: =Matchschema!A7 -> 6 | B12: =Matchschema!B7 -> Gruppspel | C12: =Matchschema!C7 -> C | D12: =Matchschema!D7 -> 46187 | E12: =Matchschema!E7 -> 00:00 | F12: =Matchschema!H7 -> Brazil | G12: =Matchschema!I7 -> Morocco | H12: =Matchschema!J7 -> MetLife Stadium, East Rutherford | I12: 3 | J12: 0 | K12: =IF(OR(I12="",J12=""),"",IF(I12>J12,"1",IF(I12=J12,"X","2"))) -> 1 | L12: =IF(Matchschema!$K7="","",IF(AND(I12=Matchschema!$K7,J12=Matchschema!$L7),Regler!$B$4,IF(K12=Matchschema!$M7,Regler!$B$5,0)))
A13: =Matchschema!A8 -> 7 | B13: =Matchschema!B8 -> Gruppspel | C13: =Matchschema!C8 -> C | D13: =Matchschema!D8 -> 46187.125 | E13: =Matchschema!E8 -> 03:00 | F13: =Matchschema!H8 -> Haiti | G13: =Matchschema!I8 -> Scotland | H13: =Matchschema!J8 -> Gillette Stadium, Foxborough | I13: 0 | J13: 2 | K13: =IF(OR(I13="",J13=""),"",IF(I13>J13,"1",IF(I13=J13,"X","2"))) -> 2 | L13: =IF(Matchschema!$K8="","",IF(AND(I13=Matchschema!$K8,J13=Matchschema!$L8),Regler!$B$4,IF(K13=Matchschema!$M8,Regler!$B$5,0)))
A14: =Matchschema!A9 -> 8 | B14: =Matchschema!B9 -> Gruppspel | C14: =Matchschema!C9 -> D | D14: =Matchschema!D9 -> 46187.25 | E14: =Matchschema!E9 -> 06:00 | F14: =Matchschema!H9 -> Australia | G14: =Matchschema!I9 -> Türkiye | H14: =Matchschema!J9 -> BC Place, Vancouver | I14: 1 | J14: 2 | K14: =IF(OR(I14="",J14=""),"",IF(I14>J14,"1",IF(I14=J14,"X","2"))) -> 2 | L14: =IF(Matchschema!$K9="","",IF(AND(I14=Matchschema!$K9,J14=Matchschema!$L9),Regler!$B$4,IF(K14=Matchschema!$M9,Regler!$B$5,0)))
A15: =Matchschema!A10 -> 9 | B15: =Matchschema!B10 -> Gruppspel | C15: =Matchschema!C10 -> E | D15: =Matchschema!D10 -> 46187.792 | E15: =Matchschema!E10 -> 19:00 | F15: =Matchschema!H10 -> Germany | G15: =Matchschema!I10 -> Curaçao | H15: =Matchschema!J10 -> NRG Stadium, Houston | I15: 4 | J15: 0 | K15: =IF(OR(I15="",J15=""),"",IF(I15>J15,"1",IF(I15=J15,"X","2"))) -> 1 | L15: =IF(Matchschema!$K10="","",IF(AND(I15=Matchschema!$K10,J15=Matchschema!$L10),Regler!$B$4,IF(K15=Matchschema!$M10,Regler!$B$5,0)))
A16: =Matchschema!A11 -> 10 | B16: =Matchschema!B11 -> Gruppspel | C16: =Matchschema!C11 -> F | D16: =Matchschema!D11 -> 46187.917 | E16: =Matchschema!E11 -> 22:00 | F16: =Matchschema!H11 -> Netherlands | G16: =Matchschema!I11 -> Japan | H16: =Matchschema!J11 -> AT&T Stadium, Arlington | I16: 2 | J16: 1 | K16: =IF(OR(I16="",J16=""),"",IF(I16>J16,"1",IF(I16=J16,"X","2"))) -> 1 | L16: =IF(Matchschema!$K11="","",IF(AND(I16=Matchschema!$K11,J16=Matchschema!$L11),Regler!$B$4,IF(K16=Matchschema!$M11,Regler!$B$5,0)))
A17: =Matchschema!A12 -> 11 | B17: =Matchschema!B12 -> Gruppspel | C17: =Matchschema!C12 -> E | D17: =Matchschema!D12 -> 46188.042 | E17: =Matchschema!E12 -> 01:00 | F17: =Matchschema!H12 -> Ivory Coast | G17: =Matchschema!I12 -> Ecuador | H17: =Matchschema!J12 -> Lincoln Financial Field, Philadelphia | I17: 0 | J17: 1 | K17: =IF(OR(I17="",J17=""),"",IF(I17>J17,"1",IF(I17=J17,"X","2"))) -> 2 | L17: =IF(Matchschema!$K12="","",IF(AND(I17=Matchschema!$K12,J17=Matchschema!$L12),Regler!$B$4,IF(K17=Matchschema!$M12,Regler!$B$5,0)))
A18: =Matchschema!A13 -> 12 | B18: =Matchschema!B13 -> Gruppspel | C18: =Matchschema!C13 -> F | D18: =Matchschema!D13 -> 46188.167 | E18: =Matchschema!E13 -> 04:00 | F18: =Matchschema!H13 -> Sweden | G18: =Matchschema!I13 -> Tunisia | H18: =Matchschema!J13 -> Estadio BBVA, Monterrey | I18: 1 | J18: 1 | K18: =IF(OR(I18="",J18=""),"",IF(I18>J18,"1",IF(I18=J18,"X","2"))) -> X | L18: =IF(Matchschema!$K13="","",IF(AND(I18=Matchschema!$K13,J18=Matchschema!$L13),Regler!$B$4,IF(K18=Matchschema!$M13,Regler!$B$5,0)))
... A110: =Matchschema!A105 -> 104 | B110: =Matchschema!B105 -> Final | C110: =Matchschema!C105 -> 0 | D110: =Matchschema!D105 -> 46222.875 | E110: =Matchschema!E105 -> 21:00 | F110: =Matchschema!H105 -> Winner Match 101 | G110: =Matchschema!I105 -> Winner Match 102 | H110: =Matchschema!J105 -> MetLife Stadium, East Rutherford, NJ | I110: 1 | J110: 1 | K110: =IF(OR(I110="",J110=""),"",IF(I110>J110,"1",IF(I110=J110,"X","2"))) -> X | L110: =IF(Matchschema!$K105="","",IF(AND(I110=Matchschema!$K105,J110=Matchschema!$L105),Regler!$B$4,IF(K110=Matchschema!$M105,Regler!$B$5,0)))

Sheet Janne
A1: VM-tips 2026 – personlig tippflik
A2: Namn: | B2: Janne | F2: Totalpoäng | G2: =SUM(L7:L110) -> 1 | I2: Exakta | J2: =SUMPRODUCT(--(I7:I110=Matchschema!$K$2:$K$105),--(J7:J110=Matchschema!$L$2:$L$105),--(Matchschema!$K$2:$K$105<>"")) -> 0 | K2: Rätt tecken | L2: =SUMPRODUCT(--(K7:K110=Matchschema!$M$2:$M$105),--(Matchschema!$M$2:$M$105<>"")) -> 1
A6: Nr | B6: Fas | C6: Grupp | D6: Datum SE | E6: Tid SE | F6: Hemmalag | G6: Bortalag | H6: Arena | I6: Tip H | J6: Tip B | K6: Tipp | L6: Poäng | M6: Kommentar
A7: =Matchschema!A2 -> 1 | B7: =Matchschema!B2 -> Gruppspel | C7: =Matchschema!C2 -> A | D7: =Matchschema!D2 -> 46184.875 | E7: =Matchschema!E2 -> 21:00 | F7: =Matchschema!H2 -> Mexico | G7: =Matchschema!I2 -> South Africa | H7: =Matchschema!J2 -> Estadio Azteca, Mexico City | I7: 3 | J7: 1 | K7: =IF(OR(I7="",J7=""),"",IF(I7>J7,"1",IF(I7=J7,"X","2"))) -> 1 | L7: =IF(Matchschema!$K2="","",IF(AND(I7=Matchschema!$K2,J7=Matchschema!$L2),Regler!$B$4,IF(K7=Matchschema!$M2,Regler!$B$5,0))) -> 1
A8: =Matchschema!A3 -> 2 | B8: =Matchschema!B3 -> Gruppspel | C8: =Matchschema!C3 -> A | D8: =Matchschema!D3 -> 46185.167 | E8: =Matchschema!E3 -> 04:00 | F8: =Matchschema!H3 -> South Korea | G8: =Matchschema!I3 -> Czechia | H8: =Matchschema!J3 -> Estadio Akron, Zapopan | I8: 1 | J8: 0 | K8: =IF(OR(I8="",J8=""),"",IF(I8>J8,"1",IF(I8=J8,"X","2"))) -> 1 | L8: =IF(Matchschema!$K3="","",IF(AND(I8=Matchschema!$K3,J8=Matchschema!$L3),Regler!$B$4,IF(K8=Matchschema!$M3,Regler!$B$5,0)))
A9: =Matchschema!A4 -> 3 | B9: =Matchschema!B4 -> Gruppspel | C9: =Matchschema!C4 -> B | D9: =Matchschema!D4 -> 46185.875 | E9: =Matchschema!E4 -> 21:00 | F9: =Matchschema!H4 -> Canada | G9: =Matchschema!I4 -> Bosnia & Herzegovina | H9: =Matchschema!J4 -> BMO Field, Toronto | I9: 2 | J9: 0 | K9: =IF(OR(I9="",J9=""),"",IF(I9>J9,"1",IF(I9=J9,"X","2"))) -> 1 | L9: =IF(Matchschema!$K4="","",IF(AND(I9=Matchschema!$K4,J9=Matchschema!$L4),Regler!$B$4,IF(K9=Matchschema!$M4,Regler!$B$5,0)))
A10: =Matchschema!A5 -> 4 | B10: =Matchschema!B5 -> Gruppspel | C10: =Matchschema!C5 -> D | D10: =Matchschema!D5 -> 46186.125 | E10: =Matchschema!E5 -> 03:00 | F10: =Matchschema!H5 -> USA | G10: =Matchschema!I5 -> Paraguay | H10: =Matchschema!J5 -> SoFi Stadium, Inglewood | I10: 1 | J10: 1 | K10: =IF(OR(I10="",J10=""),"",IF(I10>J10,"1",IF(I10=J10,"X","2"))) -> X | L10: =IF(Matchschema!$K5="","",IF(AND(I10=Matchschema!$K5,J10=Matchschema!$L5),Regler!$B$4,IF(K10=Matchschema!$M5,Regler!$B$5,0)))
A11: =Matchschema!A6 -> 5 | B11: =Matchschema!B6 -> Gruppspel | C11: =Matchschema!C6 -> B | D11: =Matchschema!D6 -> 46186.875 | E11: =Matchschema!E6 -> 21:00 | F11: =Matchschema!H6 -> Qatar | G11: =Matchschema!I6 -> Switzerland | H11: =Matchschema!J6 -> Levi’s Stadium, Santa Clara | I11: 0 | J11: 2 | K11: =IF(OR(I11="",J11=""),"",IF(I11>J11,"1",IF(I11=J11,"X","2"))) -> 2 | L11: =IF(Matchschema!$K6="","",IF(AND(I11=Matchschema!$K6,J11=Matchschema!$L6),Regler!$B$4,IF(K11=Matchschema!$M6,Regler!$B$5,0)))
A12: =Matchschema!A7 -> 6 | B12: =Matchschema!B7 -> Gruppspel | C12: =Matchschema!C7 -> C | D12: =Matchschema!D7 -> 46187 | E12: =Matchschema!E7 -> 00:00 | F12: =Matchschema!H7 -> Brazil | G12: =Matchschema!I7 -> Morocco | H12: =Matchschema!J7 -> MetLife Stadium, East Rutherford | I12: 1 | J12: 1 | K12: =IF(OR(I12="",J12=""),"",IF(I12>J12,"1",IF(I12=J12,"X","2"))) -> X | L12: =IF(Matchschema!$K7="","",IF(AND(I12=Matchschema!$K7,J12=Matchschema!$L7),Regler!$B$4,IF(K12=Matchschema!$M7,Regler!$B$5,0)))
A13: =Matchschema!A8 -> 7 | B13: =Matchschema!B8 -> Gruppspel | C13: =Matchschema!C8 -> C | D13: =Matchschema!D8 -> 46187.125 | E13: =Matchschema!E8 -> 03:00 | F13: =Matchschema!H8 -> Haiti | G13: =Matchschema!I8 -> Scotland | H13: =Matchschema!J8 -> Gillette Stadium, Foxborough | I13: 1 | J13: 2 | K13: =IF(OR(I13="",J13=""),"",IF(I13>J13,"1",IF(I13=J13,"X","2"))) -> 2 | L13: =IF(Matchschema!$K8="","",IF(AND(I13=Matchschema!$K8,J13=Matchschema!$L8),Regler!$B$4,IF(K13=Matchschema!$M8,Regler!$B$5,0)))
A14: =Matchschema!A9 -> 8 | B14: =Matchschema!B9 -> Gruppspel | C14: =Matchschema!C9 -> D | D14: =Matchschema!D9 -> 46187.25 | E14: =Matchschema!E9 -> 06:00 | F14: =Matchschema!H9 -> Australia | G14: =Matchschema!I9 -> Türkiye | H14: =Matchschema!J9 -> BC Place, Vancouver | I14: 0 | J14: 1 | K14: =IF(OR(I14="",J14=""),"",IF(I14>J14,"1",IF(I14=J14,"X","2"))) -> 2 | L14: =IF(Matchschema!$K9="","",IF(AND(I14=Matchschema!$K9,J14=Matchschema!$L9),Regler!$B$4,IF(K14=Matchschema!$M9,Regler!$B$5,0)))
A15: =Matchschema!A10 -> 9 | B15: =Matchschema!B10 -> Gruppspel | C15: =Matchschema!C10 -> E | D15: =Matchschema!D10 -> 46187.792 | E15: =Matchschema!E10 -> 19:00 | F15: =Matchschema!H10 -> Germany | G15: =Matchschema!I10 -> Curaçao | H15: =Matchschema!J10 -> NRG Stadium, Houston | I15: 4 | J15: 0 | K15: =IF(OR(I15="",J15=""),"",IF(I15>J15,"1",IF(I15=J15,"X","2"))) -> 1 | L15: =IF(Matchschema!$K10="","",IF(AND(I15=Matchschema!$K10,J15=Matchschema!$L10),Regler!$B$4,IF(K15=Matchschema!$M10,Regler!$B$5,0)))
A16: =Matchschema!A11 -> 10 | B16: =Matchschema!B11 -> Gruppspel | C16: =Matchschema!C11 -> F | D16: =Matchschema!D11 -> 46187.917 | E16: =Matchschema!E11 -> 22:00 | F16: =Matchschema!H11 -> Netherlands | G16: =Matchschema!I11 -> Japan | H16: =Matchschema!J11 -> AT&T Stadium, Arlington | I16: 1 | J16: 0 | K16: =IF(OR(I16="",J16=""),"",IF(I16>J16,"1",IF(I16=J16,"X","2"))) -> 1 | L16: =IF(Matchschema!$K11="","",IF(AND(I16=Matchschema!$K11,J16=Matchschema!$L11),Regler!$B$4,IF(K16=Matchschema!$M11,Regler!$B$5,0)))
A17: =Matchschema!A12 -> 11 | B17: =Matchschema!B12 -> Gruppspel | C17: =Matchschema!C12 -> E | D17: =Matchschema!D12 -> 46188.042 | E17: =Matchschema!E12 -> 01:00 | F17: =Matchschema!H12 -> Ivory Coast | G17: =Matchschema!I12 -> Ecuador | H17: =Matchschema!J12 -> Lincoln Financial Field, Philadelphia | I17: 1 | J17: 0 | K17: =IF(OR(I17="",J17=""),"",IF(I17>J17,"1",IF(I17=J17,"X","2"))) -> 1 | L17: =IF(Matchschema!$K12="","",IF(AND(I17=Matchschema!$K12,J17=Matchschema!$L12),Regler!$B$4,IF(K17=Matchschema!$M12,Regler!$B$5,0)))
A18: =Matchschema!A13 -> 12 | B18: =Matchschema!B13 -> Gruppspel | C18: =Matchschema!C13 -> F | D18: =Matchschema!D13 -> 46188.167 | E18: =Matchschema!E13 -> 04:00 | F18: =Matchschema!H13 -> Sweden | G18: =Matchschema!I13 -> Tunisia | H18: =Matchschema!J13 -> Estadio BBVA, Monterrey | I18: 2 | J18: 1 | K18: =IF(OR(I18="",J18=""),"",IF(I18>J18,"1",IF(I18=J18,"X","2"))) -> 1 | L18: =IF(Matchschema!$K13="","",IF(AND(I18=Matchschema!$K13,J18=Matchschema!$L13),Regler!$B$4,IF(K18=Matchschema!$M13,Regler!$B$5,0)))
... A110: =Matchschema!A105 -> 104 | B110: =Matchschema!B105 -> Final | C110: =Matchschema!C105 -> 0 | D110: =Matchschema!D105 -> 46222.875 | E110: =Matchschema!E105 -> 21:00 | F110: =Matchschema!H105 -> Winner Match 101 | G110: =Matchschema!I105 -> Winner Match 102 | H110: =Matchschema!J105 -> MetLife Stadium, East Rutherford, NJ | I110: 3 | J110: 1 | K110: =IF(OR(I110="",J110=""),"",IF(I110>J110,"1",IF(I110=J110,"X","2"))) -> 1 | L110: =IF(Matchschema!$K105="","",IF(AND(I110=Matchschema!$K105,J110=Matchschema!$L105),Regler!$B$4,IF(K110=Matchschema!$M105,Regler!$B$5,0)))

Sheet Bosse
A1: VM-tips 2026 – personlig tippflik
A2: Namn: | B2: Bosse | F2: Totalpoäng | G2: =SUM(L7:L110) -> 1 | I2: Exakta | J2: =SUMPRODUCT(--(I7:I110=Matchschema!$K$2:$K$105),--(J7:J110=Matchschema!$L$2:$L$105),--(Matchschema!$K$2:$K$105<>"")) -> 0 | K2: Rätt tecken | L2: =SUMPRODUCT(--(K7:K110=Matchschema!$M$2:$M$105),--(Matchschema!$M$2:$M$105<>"")) -> 1
A6: Nr | B6: Fas | C6: Grupp | D6: Datum SE | E6: Tid SE | F6: Hemmalag | G6: Bortalag | H6: Arena | I6: Tip H | J6: Tip B | K6: Tipp | L6: Poäng | M6: Kommentar
A7: =Matchschema!A2 -> 1 | B7: =Matchschema!B2 -> Gruppspel | C7: =Matchschema!C2 -> A | D7: =Matchschema!D2 -> 46184.875 | E7: =Matchschema!E2 -> 21:00 | F7: =Matchschema!H2 -> Mexico | G7: =Matchschema!I2 -> South Africa | H7: =Matchschema!J2 -> Estadio Azteca, Mexico City | I7: 2 | J7: 1 | K7: =IF(OR(I7="",J7=""),"",IF(I7>J7,"1",IF(I7=J7,"X","2"))) -> 1 | L7: =IF(Matchschema!$K2="","",IF(AND(I7=Matchschema!$K2,J7=Matchschema!$L2),Regler!$B$4,IF(K7=Matchschema!$M2,Regler!$B$5,0))) -> 1
A8: =Matchschema!A3 -> 2 | B8: =Matchschema!B3 -> Gruppspel | C8: =Matchschema!C3 -> A | D8: =Matchschema!D3 -> 46185.167 | E8: =Matchschema!E3 -> 04:00 | F8: =Matchschema!H3 -> South Korea | G8: =Matchschema!I3 -> Czechia | H8: =Matchschema!J3 -> Estadio Akron, Zapopan | I8: 1 | J8: 1 | K8: =IF(OR(I8="",J8=""),"",IF(I8>J8,"1",IF(I8=J8,"X","2"))) -> X | L8: =IF(Matchschema!$K3="","",IF(AND(I8=Matchschema!$K3,J8=Matchschema!$L3),Regler!$B$4,IF(K8=Matchschema!$M3,Regler!$B$5,0)))
A9: =Matchschema!A4 -> 3 | B9: =Matchschema!B4 -> Gruppspel | C9: =Matchschema!C4 -> B | D9: =Matchschema!D4 -> 46185.875 | E9: =Matchschema!E4 -> 21:00 | F9: =Matchschema!H4 -> Canada | G9: =Matchschema!I4 -> Bosnia & Herzegovina | H9: =Matchschema!J4 -> BMO Field, Toronto | I9: 2 | J9: 1 | K9: =IF(OR(I9="",J9=""),"",IF(I9>J9,"1",IF(I9=J9,"X","2"))) -> 1 | L9: =IF(Matchschema!$K4="","",IF(AND(I9=Matchschema!$K4,J9=Matchschema!$L4),Regler!$B$4,IF(K9=Matchschema!$M4,Regler!$B$5,0)))
A10: =Matchschema!A5 -> 4 | B10: =Matchschema!B5 -> Gruppspel | C10: =Matchschema!C5 -> D | D10: =Matchschema!D5 -> 46186.125 | E10: =Matchschema!E5 -> 03:00 | F10: =Matchschema!H5 -> USA | G10: =Matchschema!I5 -> Paraguay | H10: =Matchschema!J5 -> SoFi Stadium, Inglewood | I10: 2 | J10: 1 | K10: =IF(OR(I10="",J10=""),"",IF(I10>J10,"1",IF(I10=J10,"X","2"))) -> 1 | L10: =IF(Matchschema!$K5="","",IF(AND(I10=Matchschema!$K5,J10=Matchschema!$L5),Regler!$B$4,IF(K10=Matchschema!$M5,Regler!$B$5,0)))
A11: =Matchschema!A6 -> 5 | B11: =Matchschema!B6 -> Gruppspel | C11: =Matchschema!C6 -> B | D11: =Matchschema!D6 -> 46186.875 | E11: =Matchschema!E6 -> 21:00 | F11: =Matchschema!H6 -> Qatar | G11: =Matchschema!I6 -> Switzerland | H11: =Matchschema!J6 -> Levi’s Stadium, Santa Clara | I11: 0 | J11: 2 | K11: =IF(OR(I11="",J11=""),"",IF(I11>J11,"1",IF(I11=J11,"X","2"))) -> 2 | L11: =IF(Matchschema!$K6="","",IF(AND(I11=Matchschema!$K6,J11=Matchschema!$L6),Regler!$B$4,IF(K11=Matchschema!$M6,Regler!$B$5,0)))
A12: =Matchschema!A7 -> 6 | B12: =Matchschema!B7 -> Gruppspel | C12: =Matchschema!C7 -> C | D12: =Matchschema!D7 -> 46187 | E12: =Matchschema!E7 -> 00:00 | F12: =Matchschema!H7 -> Brazil | G12: =Matchschema!I7 -> Morocco | H12: =Matchschema!J7 -> MetLife Stadium, East Rutherford | I12: 2 | J12: 1 | K12: =IF(OR(I12="",J12=""),"",IF(I12>J12,"1",IF(I12=J12,"X","2"))) -> 1 | L12: =IF(Matchschema!$K7="","",IF(AND(I12=Matchschema!$K7,J12=Matchschema!$L7),Regler!$B$4,IF(K12=Matchschema!$M7,Regler!$B$5,0)))
A13: =Matchschema!A8 -> 7 | B13: =Matchschema!B8 -> Gruppspel | C13: =Matchschema!C8 -> C | D13: =Matchschema!D8 -> 46187.125 | E13: =Matchschema!E8 -> 03:00 | F13: =Matchschema!H8 -> Haiti | G13: =Matchschema!I8 -> Scotland | H13: =Matchschema!J8 -> Gillette Stadium, Foxborough | I13: 1 | J13: 1 | K13: =IF(OR(I13="",J13=""),"",IF(I13>J13,"1",IF(I13=J13,"X","2"))) -> X | L13: =IF(Matchschema!$K8="","",IF(AND(I13=Matchschema!$K8,J13=Matchschema!$L8),Regler!$B$4,IF(K13=Matchschema!$M8,Regler!$B$5,0)))
A14: =Matchschema!A9 -> 8 | B14: =Matchschema!B9 -> Gruppspel | C14: =Matchschema!C9 -> D | D14: =Matchschema!D9 -> 46187.25 | E14: =Matchschema!E9 -> 06:00 | F14: =Matchschema!H9 -> Australia | G14: =Matchschema!I9 -> Türkiye | H14: =Matchschema!J9 -> BC Place, Vancouver | I14: 1 | J14: 2 | K14: =IF(OR(I14="",J14=""),"",IF(I14>J14,"1",IF(I14=J14,"X","2"))) -> 2 | L14: =IF(Matchschema!$K9="","",IF(AND(I14=Matchschema!$K9,J14=Matchschema!$L9),Regler!$B$4,IF(K14=Matchschema!$M9,Regler!$B$5,0)))
A15: =Matchschema!A10 -> 9 | B15: =Matchschema!B10 -> Gruppspel | C15: =Matchschema!C10 -> E | D15: =Matchschema!D10 -> 46187.792 | E15: =Matchschema!E10 -> 19:00 | F15: =Matchschema!H10 -> Germany | G15: =Matchschema!I10 -> Curaçao | H15: =Matchschema!J10 -> NRG Stadium, Houston | I15: 4 | J15: 0 | K15: =IF(OR(I15="",J15=""),"",IF(I15>J15,"1",IF(I15=J15,"X","2"))) -> 1 | L15: =IF(Matchschema!$K10="","",IF(AND(I15=Matchschema!$K10,J15=Matchschema!$L10),Regler!$B$4,IF(K15=Matchschema!$M10,Regler!$B$5,0)))
A16: =Matchschema!A11 -> 10 | B16: =Matchschema!B11 -> Gruppspel | C16: =Matchschema!C11 -> F | D16: =Matchschema!D11 -> 46187.917 | E16: =Matchschema!E11 -> 22:00 | F16: =Matchschema!H11 -> Netherlands | G16: =Matchschema!I11 -> Japan | H16: =Matchschema!J11 -> AT&T Stadium, Arlington | I16: 2 | J16: 1 | K16: =IF(OR(I16="",J16=""),"",IF(I16>J16,"1",IF(I16=J16,"X","2"))) -> 1 | L16: =IF(Matchschema!$K11="","",IF(AND(I16=Matchschema!$K11,J16=Matchschema!$L11),Regler!$B$4,IF(K16=Matchschema!$M11,Regler!$B$5,0)))
A17: =Matchschema!A12 -> 11 | B17: =Matchschema!B12 -> Gruppspel | C17: =Matchschema!C12 -> E | D17: =Matchschema!D12 -> 46188.042 | E17: =Matchschema!E12 -> 01:00 | F17: =Matchschema!H12 -> Ivory Coast | G17: =Matchschema!I12 -> Ecuador | H17: =Matchschema!J12 -> Lincoln Financial Field, Philadelphia | I17: 1 | J17: 1 | K17: =IF(OR(I17="",J17=""),"",IF(I17>J17,"1",IF(I17=J17,"X","2"))) -> X | L17: =IF(Matchschema!$K12="","",IF(AND(I17=Matchschema!$K12,J17=Matchschema!$L12),Regler!$B$4,IF(K17=Matchschema!$M12,Regler!$B$5,0)))
A18: =Matchschema!A13 -> 12 | B18: =Matchschema!B13 -> Gruppspel | C18: =Matchschema!C13 -> F | D18: =Matchschema!D13 -> 46188.167 | E18: =Matchschema!E13 -> 04:00 | F18: =Matchschema!H13 -> Sweden | G18: =Matchschema!I13 -> Tunisia | H18: =Matchschema!J13 -> Estadio BBVA, Monterrey | I18: 2 | J18: 0 | K18: =IF(OR(I18="",J18=""),"",IF(I18>J18,"1",IF(I18=J18,"X","2"))) -> 1 | L18: =IF(Matchschema!$K13="","",IF(AND(I18=Matchschema!$K13,J18=Matchschema!$L13),Regler!$B$4,IF(K18=Matchschema!$M13,Regler!$B$5,0)))
... A110: =Matchschema!A105 -> 104 | B110: =Matchschema!B105 -> Final | C110: =Matchschema!C105 -> 0 | D110: =Matchschema!D105 -> 46222.875 | E110: =Matchschema!E105 -> 21:00 | F110: =Matchschema!H105 -> Winner Match 101 | G110: =Matchschema!I105 -> Winner Match 102 | H110: =Matchschema!J105 -> MetLife Stadium, East Rutherford, NJ | I110: 1 | J110: 2 | K110: =IF(OR(I110="",J110=""),"",IF(I110>J110,"1",IF(I110=J110,"X","2"))) -> 2 | L110: =IF(Matchschema!$K105="","",IF(AND(I110=Matchschema!$K105,J110=Matchschema!$L105),Regler!$B$4,IF(K110=Matchschema!$M105,Regler!$B$5,0)))

Sheet Stina
A1: VM-tips 2026 – personlig tippflik
A2: Namn: | B2: Stina | F2: Totalpoäng | G2: =SUM(L7:L110) -> 3 | I2: Exakta | J2: =SUMPRODUCT(--(I7:I110=Matchschema!$K$2:$K$105),--(J7:J110=Matchschema!$L$2:$L$105),--(Matchschema!$K$2:$K$105<>"")) -> 1 | K2: Rätt tecken | L2: =SUMPRODUCT(--(K7:K110=Matchschema!$M$2:$M$105),--(Matchschema!$M$2:$M$105<>"")) -> 1
A6: Nr | B6: Fas | C6: Grupp | D6: Datum SE | E6: Tid SE | F6: Hemmalag | G6: Bortalag | H6: Arena | I6: Tip H | J6: Tip B | K6: Tipp | L6: Poäng | M6: Kommentar
A7: =Matchschema!A2 -> 1 | B7: =Matchschema!B2 -> Gruppspel | C7: =Matchschema!C2 -> A | D7: =Matchschema!D2 -> 46184.875 | E7: =Matchschema!E2 -> 21:00 | F7: =Matchschema!H2 -> Mexico | G7: =Matchschema!I2 -> South Africa | H7: =Matchschema!J2 -> Estadio Azteca, Mexico City | I7: 2 | J7: 0 | K7: =IF(OR(I7="",J7=""),"",IF(I7>J7,"1",IF(I7=J7,"X","2"))) -> 1 | L7: =IF(Matchschema!$K2="","",IF(AND(I7=Matchschema!$K2,J7=Matchschema!$L2),Regler!$B$4,IF(K7=Matchschema!$M2,Regler!$B$5,0))) -> 3
A8: =Matchschema!A3 -> 2 | B8: =Matchschema!B3 -> Gruppspel | C8: =Matchschema!C3 -> A | D8: =Matchschema!D3 -> 46185.167 | E8: =Matchschema!E3 -> 04:00 | F8: =Matchschema!H3 -> South Korea | G8: =Matchschema!I3 -> Czechia | H8: =Matchschema!J3 -> Estadio Akron, Zapopan | I8: 1 | J8: 1 | K8: =IF(OR(I8="",J8=""),"",IF(I8>J8,"1",IF(I8=J8,"X","2"))) -> X | L8: =IF(Matchschema!$K3="","",IF(AND(I8=Matchschema!$K3,J8=Matchschema!$L3),Regler!$B$4,IF(K8=Matchschema!$M3,Regler!$B$5,0)))
A9: =Matchschema!A4 -> 3 | B9: =Matchschema!B4 -> Gruppspel | C9: =Matchschema!C4 -> B | D9: =Matchschema!D4 -> 46185.875 | E9: =Matchschema!E4 -> 21:00 | F9: =Matchschema!H4 -> Canada | G9: =Matchschema!I4 -> Bosnia & Herzegovina | H9: =Matchschema!J4 -> BMO Field, Toronto | I9: 2 | J9: 1 | K9: =IF(OR(I9="",J9=""),"",IF(I9>J9,"1",IF(I9=J9,"X","2"))) -> 1 | L9: =IF(Matchschema!$K4="","",IF(AND(I9=Matchschema!$K4,J9=Matchschema!$L4),Regler!$B$4,IF(K9=Matchschema!$M4,Regler!$B$5,0)))
A10: =Matchschema!A5 -> 4 | B10: =Matchschema!B5 -> Gruppspel | C10: =Matchschema!C5 -> D | D10: =Matchschema!D5 -> 46186.125 | E10: =Matchschema!E5 -> 03:00 | F10: =Matchschema!H5 -> USA | G10: =Matchschema!I5 -> Paraguay | H10: =Matchschema!J5 -> SoFi Stadium, Inglewood | I10: 1 | J10: 1 | K10: =IF(OR(I10="",J10=""),"",IF(I10>J10,"1",IF(I10=J10,"X","2"))) -> X | L10: =IF(Matchschema!$K5="","",IF(AND(I10=Matchschema!$K5,J10=Matchschema!$L5),Regler!$B$4,IF(K10=Matchschema!$M5,Regler!$B$5,0)))
A11: =Matchschema!A6 -> 5 | B11: =Matchschema!B6 -> Gruppspel | C11: =Matchschema!C6 -> B | D11: =Matchschema!D6 -> 46186.875 | E11: =Matchschema!E6 -> 21:00 | F11: =Matchschema!H6 -> Qatar | G11: =Matchschema!I6 -> Switzerland | H11: =Matchschema!J6 -> Levi’s Stadium, Santa Clara | I11: 0 | J11: 2 | K11: =IF(OR(I11="",J11=""),"",IF(I11>J11,"1",IF(I11=J11,"X","2"))) -> 2 | L11: =IF(Matchschema!$K6="","",IF(AND(I11=Matchschema!$K6,J11=Matchschema!$L6),Regler!$B$4,IF(K11=Matchschema!$M6,Regler!$B$5,0)))
A12: =Matchschema!A7 -> 6 | B12: =Matchschema!B7 -> Gruppspel | C12: =Matchschema!C7 -> C | D12: =Matchschema!D7 -> 46187 | E12: =Matchschema!E7 -> 00:00 | F12: =Matchschema!H7 -> Brazil | G12: =Matchschema!I7 -> Morocco | H12: =Matchschema!J7 -> MetLife Stadium, East Rutherford | I12: 2 | J12: 0 | K12: =IF(OR(I12="",J12=""),"",IF(I12>J12,"1",IF(I12=J12,"X","2"))) -> 1 | L12: =IF(Matchschema!$K7="","",IF(AND(I12=Matchschema!$K7,J12=Matchschema!$L7),Regler!$B$4,IF(K12=Matchschema!$M7,Regler!$B$5,0)))
A13: =Matchschema!A8 -> 7 | B13: =Matchschema!B8 -> Gruppspel | C13: =Matchschema!C8 -> C | D13: =Matchschema!D8 -> 46187.125 | E13: =Matchschema!E8 -> 03:00 | F13: =Matchschema!H8 -> Haiti | G13: =Matchschema!I8 -> Scotland | H13: =Matchschema!J8 -> Gillette Stadium, Foxborough | I13: 0 | J13: 2 | K13: =IF(OR(I13="",J13=""),"",IF(I13>J13,"1",IF(I13=J13,"X","2"))) -> 2 | L13: =IF(Matchschema!$K8="","",IF(AND(I13=Matchschema!$K8,J13=Matchschema!$L8),Regler!$B$4,IF(K13=Matchschema!$M8,Regler!$B$5,0)))
A14: =Matchschema!A9 -> 8 | B14: =Matchschema!B9 -> Gruppspel | C14: =Matchschema!C9 -> D | D14: =Matchschema!D9 -> 46187.25 | E14: =Matchschema!E9 -> 06:00 | F14: =Matchschema!H9 -> Australia | G14: =Matchschema!I9 -> Türkiye | H14: =Matchschema!J9 -> BC Place, Vancouver | I14: 1 | J14: 1 | K14: =IF(OR(I14="",J14=""),"",IF(I14>J14,"1",IF(I14=J14,"X","2"))) -> X | L14: =IF(Matchschema!$K9="","",IF(AND(I14=Matchschema!$K9,J14=Matchschema!$L9),Regler!$B$4,IF(K14=Matchschema!$M9,Regler!$B$5,0)))
